Workbook

Sheet 요약
A1: Concord 재무 모델
A2: 프리미엄 1:1 대면 과외 · 서울·동탄 — 3개년 (2026 H2 ~ 2029 H1) · 기준 2026-07
A4: 핵심 지표
A5: 항목 | B5: 값 | C5: 근거
A6: 요금 (4주 정액 선불) | B6: 중등 38·55·76·106만 / 고등 43·58·78·112만 원 | C6: 8플랜 확정가 · 할인 구조 없음
A7: 강사 시급 | B7: ='플랜·마진표'!B4 | C7: 기본 30,000원/h · 프리셋 32/34/40k 관리자 수동 지정
A8: 평균 마진율 (8플랜) | B8: ='플랜·마진표'!I17 | C8: 플랜·마진표 — 범위 29.9~42.0%
A9: 학생 1인 월 기여마진 | B9: =TEXT(BEP!B9,"#,##0")&"원(파일럿 믹스) ~ "&TEXT('플랜·마진표'!H17,"#,##0")&"원(8플랜 평균)" | C9: BEP · 플랜·마진표
A10: BEP | B10: ="Phase 1 활성 "&BEP!B24&"명 / Phase 2 활성 "&BEP!B25&"명" | C10: 운영 밴드 5~7명 (복합 스트레스 포함)
A11: LTV/CAC 목표 | B11: 5:1 이상 (기본) | C11: CAC·채널 — 파일럿 CAC 상한 20만 원
A12: 지원금 Ask | B12: 1억 원 — 인건비 30 · 사업화 25 · 마케팅 25 · 운영 15 · 예비 5(%) | C12: CAC·채널 배분표
A13: 시장 (2025 실측) | B13: 사교육 총액 27.5조 원 · 참여 학생 1인당 월 60.4만 원 | C13: 국가데이터처 2025년 초중고 사교육비조사
A15: 3개년 전망 (램프업 월별 적산)
A16: 시나리오 | B16: 3년말 활성 학생 | C16: 누적 수업료 매출(원) | D16: 누적 기여마진(원)
A17: 보수 | B17: =램프업!B54 | C17: =램프업!C54 | D17: =램프업!D54
A18: 기본 | B18: =램프업!B55 | C18: =램프업!C55 | D18: =램프업!D55
A19: 공격 | B19: =램프업!B56 | C19: =램프업!C56 | D19: =램프업!D56
A21: 가정 셀(노란 채움)을 바꾸면 전 시트가 재계산된다. 시급·객단가·믹스·활성 학생 앵커가 가정.

Sheet 플랜·마진표
A1: 플랜별 기여마진 (8플랜 · 4주 정액 선불)
A3: 가정 (노란 채움 셀 — 값 변경 시 전체 재계산)
A4: 기본 시급(원/h) | B4: 30000 | C4: 확정 2026-07-04 · 차등은 관리자 수동 프리셋만
A5: PG 수수료율 | B5: 0.022 | C5: 토스페이먼츠
A6: 원천징수율 | B6: 0.033 | C6: 강사 정산 시 공제 — 회사 원가는 강사비 총액 기준
A8: 플랜 | B8: 월 수업 시간(h) | C8: 월 요금(원) | D8: 강사비(원) | E8: 원천징수 3.3%(원) | F8: 강사 실지급(원) | G8: PG(원) | H8: 기여마진(원) | I8: 마진율
A9: 중등 · 주1 · 2h | B9: 8 | C9: 380000 | D9: =B9*$B$4 | E9: =D9*$B$6 | F9: =D9-E9 | G9: =C9*$B$5 | H9: =C9-D9-G9 | I9: =H9/C9
A10: 중등 · 주1 · 3h | B10: 12 | C10: 550000 | D10: =B10*$B$4 | E10: =D10*$B$6 | F10: =D10-E10 | G10: =C10*$B$5 | H10: =C10-D10-G10 | I10: =H10/C10
A11: 중등 · 주2 · 2h | B11: 16 | C11: 760000 | D11: =B11*$B$4 | E11: =D11*$B$6 | F11: =D11-E11 | G11: =C11*$B$5 | H11: =C11-D11-G11 | I11: =H11/C11
A12: 중등 · 주2 · 3h | B12: 24 | C12: 1060000 | D12: =B12*$B$4 | E12: =D12*$B$6 | F12: =D12-E12 | G12: =C12*$B$5 | H12: =C12-D12-G12 | I12: =H12/C12
A13: 고등 · 주1 · 2h | B13: 8 | C13: 430000 | D13: =B13*$B$4 | E13: =D13*$B$6 | F13: =D13-E13 | G13: =C13*$B$5 | H13: =C13-D13-G13 | I13: =H13/C13
A14: 고등 · 주1 · 3h | B14: 12 | C14: 580000 | D14: =B14*$B$4 | E14: =D14*$B$6 | F14: =D14-E14 | G14: =C14*$B$5 | H14: =C14-D14-G14 | I14: =H14/C14
A15: 고등 · 주2 · 2h | B15: 16 | C15: 780000 | D15: =B15*$B$4 | E15: =D15*$B$6 | F15: =D15-E15 | G15: =C15*$B$5 | H15: =C15-D15-G15 | I15: =H15/C15
A16: 고등 · 주2 · 3h | B16: 24 | C16: 1120000 | D16: =B16*$B$4 | E16: =D16*$B$6 | F16: =D16-E16 | G16: =C16*$B$5 | H16: =C16-D16-G16 | I16: =H16/C16
A17: 8플랜 산술평균 | B17: =AVERAGE(B9:B16) | C17: =AVERAGE(C9:C16) | D17: =AVERAGE(D9:D16) | E17: =AVERAGE(E9:E16) | F17: =AVERAGE(F9:F16) | G17: =AVERAGE(G9:G16) | H17: =AVERAGE(H9:H16) | I17: =H17/C17
A20: 시급 프리셋별 민감도 (요금 불변 · PG 동일)
A21: 플랜 | B21: 강사비(원) | F21: 기여마진(원) | J21: 마진율
A22: 시급(원/h) | B22: 30000 | C22: 32000 | D22: 34000 | E22: 40000 | F22: =B22 | G22: =C22 | H22: =D22 | I22: =E22 | J22: =B22 | K22: =C22 | L22: =D22 | M22: =E22
A23: 중등 · 주1 · 2h | B23: =$B9*B$22 | C23: =$B9*C$22 | D23: =$B9*D$22 | E23: =$B9*E$22 | F23: =$C9-$B9*F$22-$C9*$B$5 | G23: =$C9-$B9*G$22-$C9*$B$5 | H23: =$C9-$B9*H$22-$C9*$B$5 | I23: =$C9-$B9*I$22-$C9*$B$5 | J23: =($C9-$B9*J$22-$C9*$B$5)/$C9 | K23: =($C9-$B9*K$22-$C9*$B$5)/$C9 | L23: =($C9-$B9*L$22-$C9*$B$5)/$C9 | M23: =($C9-$B9*M$22-$C9*$B$5)/$C9
A24: 중등 · 주1 · 3h | B24: =$B10*B$22 | C24: =$B10*C$22 | D24: =$B10*D$22 | E24: =$B10*E$22 | F24: =$C10-$B10*F$22-$C10*$B$5 | G24: =$C10-$B10*G$22-$C10*$B$5 | H24: =$C10-$B10*H$22-$C10*$B$5 | I24: =$C10-$B10*I$22-$C10*$B$5 | J24: =($C10-$B10*J$22-$C10*$B$5)/$C10 | K24: =($C10-$B10*K$22-$C10*$B$5)/$C10 | L24: =($C10-$B10*L$22-$C10*$B$5)/$C10 | M24: =($C10-$B10*M$22-$C10*$B$5)/$C10
A25: 중등 · 주2 · 2h | B25: =$B11*B$22 | C25: =$B11*C$22 | D25: =$B11*D$22 | E25: =$B11*E$22 | F25: =$C11-$B11*F$22-$C11*$B$5 | G25: =$C11-$B11*G$22-$C11*$B$5 | H25: =$C11-$B11*H$22-$C11*$B$5 | I25: =$C11-$B11*I$22-$C11*$B$5 | J25: =($C11-$B11*J$22-$C11*$B$5)/$C11 | K25: =($C11-$B11*K$22-$C11*$B$5)/$C11 | L25: =($C11-$B11*L$22-$C11*$B$5)/$C11 | M25: =($C11-$B11*M$22-$C11*$B$5)/$C11
A26: 중등 · 주2 · 3h | B26: =$B12*B$22 | C26: =$B12*C$22 | D26: =$B12*D$22 | E26: =$B12*E$22 | F26: =$C12-$B12*F$22-$C12*$B$5 | G26: =$C12-$B12*G$22-$C12*$B$5 | H26: =$C12-$B12*H$22-$C12*$B$5 | I26: =$C12-$B12*I$22-$C12*$B$5 | J26: =($C12-$B12*J$22-$C12*$B$5)/$C12 | K26: =($C12-$B12*K$22-$C12*$B$5)/$C12 | L26: =($C12-$B12*L$22-$C12*$B$5)/$C12 | M26: =($C12-$B12*M$22-$C12*$B$5)/$C12
A27: 고등 · 주1 · 2h | B27: =$B13*B$22 | C27: =$B13*C$22 | D27: =$B13*D$22 | E27: =$B13*E$22 | F27: =$C13-$B13*F$22-$C13*$B$5 | G27: =$C13-$B13*G$22-$C13*$B$5 | H27: =$C13-$B13*H$22-$C13*$B$5 | I27: =$C13-$B13*I$22-$C13*$B$5 | J27: =($C13-$B13*J$22-$C13*$B$5)/$C13 | K27: =($C13-$B13*K$22-$C13*$B$5)/$C13 | L27: =($C13-$B13*L$22-$C13*$B$5)/$C13 | M27: =($C13-$B13*M$22-$C13*$B$5)/$C13
A28: 고등 · 주1 · 3h | B28: =$B14*B$22 | C28: =$B14*C$22 | D28: =$B14*D$22 | E28: =$B14*E$22 | F28: =$C14-$B14*F$22-$C14*$B$5 | G28: =$C14-$B14*G$22-$C14*$B$5 | H28: =$C14-$B14*H$22-$C14*$B$5 | I28: =$C14-$B14*I$22-$C14*$B$5 | J28: =($C14-$B14*J$22-$C14*$B$5)/$C14 | K28: =($C14-$B14*K$22-$C14*$B$5)/$C14 | L28: =($C14-$B14*L$22-$C14*$B$5)/$C14 | M28: =($C14-$B14*M$22-$C14*$B$5)/$C14
A29: 고등 · 주2 · 2h | B29: =$B15*B$22 | C29: =$B15*C$22 | D29: =$B15*D$22 | E29: =$B15*E$22 | F29: =$C15-$B15*F$22-$C15*$B$5 | G29: =$C15-$B15*G$22-$C15*$B$5 | H29: =$C15-$B15*H$22-$C15*$B$5 | I29: =$C15-$B15*I$22-$C15*$B$5 | J29: =($C15-$B15*J$22-$C15*$B$5)/$C15 | K29: =($C15-$B15*K$22-$C15*$B$5)/$C15 | L29: =($C15-$B15*L$22-$C15*$B$5)/$C15 | M29: =($C15-$B15*M$22-$C15*$B$5)/$C15
A30: 고등 · 주2 · 3h | B30: =$B16*B$22 | C30: =$B16*C$22 | D30: =$B16*D$22 | E30: =$B16*E$22 | F30: =$C16-$B16*F$22-$C16*$B$5 | G30: =$C16-$B16*G$22-$C16*$B$5 | H30: =$C16-$B16*H$22-$C16*$B$5 | I30: =$C16-$B16*I$22-$C16*$B$5 | J30: =($C16-$B16*J$22-$C16*$B$5)/$C16 | K30: =($C16-$B16*K$22-$C16*$B$5)/$C16 | L30: =($C16-$B16*L$22-$C16*$B$5)/$C16 | M30: =($C16-$B16*M$22-$C16*$B$5)/$C16
A32: 주: 프리셋 32,000/34,000/40,000원은 관리자 수동 지정 예외(차등시급 시스템 보류). 기본 시급 30,000원이 정산 기준.

Sheet BEP
A1: 손익분기 (BEP)
A3: 학생 1인 월 기여마진 — 파일럿 믹스
A4: 객단가(월·원) | B4: 650000 | C4: 파일럿 예상 믹스 가중
A5: 월 평균 수업 시간(h) | B5: 14 | C5: 믹스 가중평균
A6: 강사 시급(원/h) | B6: ='플랜·마진표'!B4 | C6: 플랜·마진표 가정 연동
A7: 강사비(원) | B7: =B5*B6
A8: PG(원) | B8: =B4*'플랜·마진표'!B5
A9: 학생 1인 월 기여마진(원) | B9: =B4-B7-B8 | C9: 약 215,700원
A11: 월 고정비 내역
A12: 항목 | B12: Phase 1 (~30명) | C12: Phase 2 (30명 초과)
A13: 대표자 인건비 | B13: 지원금 충당 | C13: 지원금 → 매출 자립
A14: 매니저 인건비 | B14: 대표자 겸무 (0원) | C14: 성과급 변동비 구조
A15: 인프라(Vercel·Supabase·토스) | B15: 약 10~30만 원 | C15: 규모 비례·소액
A16: 마케팅 | B16: 30~50만 → 100~300만 원 | C16: 200~500만 원
A17: 사무·법무·세무·통신 | B17: 20~30만 원 | C17: 30~50만 원
A18: 배상책임보험 | B18: 5~10만 원 | C18: 10만 원
A19: 합계 | B19: 약 65~120만 원 | C19: 약 250~500만 원
A21: BEP 계산 (고정비 가정 셀)
A22: Phase 1 고정비(원/월) | B22: 1000000
A23: Phase 2 고정비(원/월) | B23: 3000000
A24: Phase 1 BEP(활성 학생) | B24: =CEILING(B22/B9,1)
A25: Phase 2 BEP(활성 학생) | B25: =CEILING(B23/B9,1)
A27: 주: 복합 스트레스(시급 32,500원 + 객단가 -5% + 이탈 8%)에서도 BEP 7명 — 운영 밴드 5~7명.
A29: 민감도 — 시급 × 플랜 믹스
B30: 파일럿 믹스 (650,000원 · 14h) | E30: 8플랜 평균 (707,500원 · 15h)
A31: 시급(원/h) | B31: 기여마진(원) | C31: BEP P1(명) | D31: BEP P2(명) | E31: 기여마진(원) | F31: BEP P1(명) | G31: BEP P2(명)
A32: 30000 | B32: =$B$4-$B$5*A32-$B$8 | C32: =CEILING($B$22/B32,1) | D32: =CEILING($B$23/B32,1) | E32: =$B$38-$B$39*A32-$B$38*'플랜·마진표'!$B$5 | F32: =CEILING($B$22/E32,1) | G32: =CEILING($B$23/E32,1)
A33: 32000 | B33: =$B$4-$B$5*A33-$B$8 | C33: =CEILING($B$22/B33,1) | D33: =CEILING($B$23/B33,1) | E33: =$B$38-$B$39*A33-$B$38*'플랜·마진표'!$B$5 | F33: =CEILING($B$22/E33,1) | G33: =CEILING($B$23/E33,1)
A34: 34000 | B34: =$B$4-$B$5*A34-$B$8 | C34: =CEILING($B$22/B34,1) | D34: =CEILING($B$23/B34,1) | E34: =$B$38-$B$39*A34-$B$38*'플랜·마진표'!$B$5 | F34: =CEILING($B$22/E34,1) | G34: =CEILING($B$23/E34,1)
A35: 40000 | B35: =$B$4-$B$5*A35-$B$8 | C35: =CEILING($B$22/B35,1) | D35: =CEILING($B$23/B35,1) | E35: =$B$38-$B$39*A35-$B$38*'플랜·마진표'!$B$5 | F35: =CEILING($B$22/E35,1) | G35: =CEILING($B$23/E35,1)
A38: 8플랜 평균 객단가(원) | B38: ='플랜·마진표'!C17
A39: 8플랜 평균 수업 시간(h) | B39: ='플랜·마진표'!B17

Sheet 램프업
A1: 램프업 — 3시나리오 월별 36개월 (2026-07 ~ 2029-06)
A3: 가정
A4: 객단가(월·원) | B4: =BEP!B4 | C4: BEP 시트 가정 연동
A5: 학생 1인 월 기여마진(원) | B5: =BEP!B9
A7: 반기말 활성 학생 (가정) | B7: 2026 H2 | C7: 2027 H1 | D7: 2027 H2 | E7: 2028 H1 | F7: 2028 H2 | G7: 2029 H1
A8: 보수 | B8: 10 | C8: 25 | D8: 45 | E8: 70 | F8: 90 | G8: 110
A9: 기본 | B9: 15 | C9: 40 | D9: 75 | E9: 115 | F9: 145 | G9: 170
A10: 공격 | B10: 20 | C10: 55 | D10: 110 | E10: 170 | F10: 220 | G10: 270
A13: 월차 | B13: 년월 | C13: 보수 | H13: 기본 | M13: 공격
C14: 활성 학생 | D14: 매출(원) | E14: 기여마진(원) | F14: 누적 매출(원) | G14: 누적 기여마진(원) | H14: 활성 학생 | I14: 매출(원) | J14: 기여마진(원) | K14: 누적 매출(원) | L14: 누적 기여마진(원) | M14: 활성 학생 | N14: 매출(원) | O14: 기여마진(원) | P14: 누적 매출(원) | Q14: 누적 기여마진(원)
A15: 1 | B15: 2026-07 | C15: =ROUND(0+(B8-0)*1/6,0) | D15: =C15*$B$4 | E15: =C15*$B$5 | F15: =D15 | G15: =E15 | H15: =ROUND(0+(B9-0)*1/6,0) | I15: =H15*$B$4 | J15: =H15*$B$5 | K15: =I15 | L15: =J15 | M15: =ROUND(0+(B10-0)*1/6,0) | N15: =M15*$B$4 | O15: =M15*$B$5 | P15: =N15 | Q15: =O15
A16: 2 | B16: 2026-08 | C16: =ROUND(0+(B8-0)*2/6,0) | D16: =C16*$B$4 | E16: =C16*$B$5 | F16: =F15+D16 | G16: =G15+E16 | H16: =ROUND(0+(B9-0)*2/6,0) | I16: =H16*$B$4 | J16: =H16*$B$5 | K16: =K15+I16 | L16: =L15+J16 | M16: =ROUND(0+(B10-0)*2/6,0) | N16: =M16*$B$4 | O16: =M16*$B$5 | P16: =P15+N16 | Q16: =Q15+O16
A17: 3 | B17: 2026-09 | C17: =ROUND(0+(B8-0)*3/6,0) | D17: =C17*$B$4 | E17: =C17*$B$5 | F17: =F16+D17 | G17: =G16+E17 | H17: =ROUND(0+(B9-0)*3/6,0) | I17: =H17*$B$4 | J17: =H17*$B$5 | K17: =K16+I17 | L17: =L16+J17 | M17: =ROUND(0+(B10-0)*3/6,0) | N17: =M17*$B$4 | O17: =M17*$B$5 | P17: =P16+N17 | Q17: =Q16+O17
A18: 4 | B18: 2026-10 | C18: =ROUND(0+(B8-0)*4/6,0) | D18: =C18*$B$4 | E18: =C18*$B$5 | F18: =F17+D18 | G18: =G17+E18 | H18: =ROUND(0+(B9-0)*4/6,0) | I18: =H18*$B$4 | J18: =H18*$B$5 | K18: =K17+I18 | L18: =L17+J18 | M18: =ROUND(0+(B10-0)*4/6,0) | N18: =M18*$B$4 | O18: =M18*$B$5 | P18: =P17+N18 | Q18: =Q17+O18
A19: 5 | B19: 2026-11 | C19: =ROUND(0+(B8-0)*5/6,0) | D19: =C19*$B$4 | E19: =C19*$B$5 | F19: =F18+D19 | G19: =G18+E19 | H19: =ROUND(0+(B9-0)*5/6,0) | I19: =H19*$B$4 | J19: =H19*$B$5 | K19: =K18+I19 | L19: =L18+J19 | M19: =ROUND(0+(B10-0)*5/6,0) | N19: =M19*$B$4 | O19: =M19*$B$5 | P19: =P18+N19 | Q19: =Q18+O19
A20: 6 | B20: 2026-12 | C20: =ROUND(0+(B8-0)*6/6,0) | D20: =C20*$B$4 | E20: =C20*$B$5 | F20: =F19+D20 | G20: =G19+E20 | H20: =ROUND(0+(B9-0)*6/6,0) | I20: =H20*$B$4 | J20: =H20*$B$5 | K20: =K19+I20 | L20: =L19+J20 | M20: =ROUND(0+(B10-0)*6/6,0) | N20: =M20*$B$4 | O20: =M20*$B$5 | P20: =P19+N20 | Q20: =Q19+O20
A21: 7 | B21: 2027-01 | C21: =ROUND(B8+(C8-B8)*1/6,0) | D21: =C21*$B$4 | E21: =C21*$B$5 | F21: =F20+D21 | G21: =G20+E21 | H21: =ROUND(B9+(C9-B9)*1/6,0) | I21: =H21*$B$4 | J21: =H21*$B$5 | K21: =K20+I21 | L21: =L20+J21 | M21: =ROUND(B10+(C10-B10)*1/6,0) | N21: =M21*$B$4 | O21: =M21*$B$5 | P21: =P20+N21 | Q21: =Q20+O21
A22: 8 | B22: 2027-02 | C22: =ROUND(B8+(C8-B8)*2/6,0) | D22: =C22*$B$4 | E22: =C22*$B$5 | F22: =F21+D22 | G22: =G21+E22 | H22: =ROUND(B9+(C9-B9)*2/6,0) | I22: =H22*$B$4 | J22: =H22*$B$5 | K22: =K21+I22 | L22: =L21+J22 | M22: =ROUND(B10+(C10-B10)*2/6,0) | N22: =M22*$B$4 | O22: =M22*$B$5 | P22: =P21+N22 | Q22: =Q21+O22
A23: 9 | B23: 2027-03 | C23: =ROUND(B8+(C8-B8)*3/6,0) | D23: =C23*$B$4 | E23: =C23*$B$5 | F23: =F22+D23 | G23: =G22+E23 | H23: =ROUND(B9+(C9-B9)*3/6,0) | I23: =H23*$B$4 | J23: =H23*$B$5 | K23: =K22+I23 | L23: =L22+J23 | M23: =ROUND(B10+(C10-B10)*3/6,0) | N23: =M23*$B$4 | O23: =M23*$B$5 | P23: =P22+N23 | Q23: =Q22+O23
A24: 10 | B24: 2027-04 | C24: =ROUND(B8+(C8-B8)*4/6,0) | D24: =C24*$B$4 | E24: =C24*$B$5 | F24: =F23+D24 | G24: =G23+E24 | H24: =ROUND(B9+(C9-B9)*4/6,0) | I24: =H24*$B$4 | J24: =H24*$B$5 | K24: =K23+I24 | L24: =L23+J24 | M24: =ROUND(B10+(C10-B10)*4/6,0) | N24: =M24*$B$4 | O24: =M24*$B$5 | P24: =P23+N24 | Q24: =Q23+O24
A25: 11 | B25: 2027-05 | C25: =ROUND(B8+(C8-B8)*5/6,0) | D25: =C25*$B$4 | E25: =C25*$B$5 | F25: =F24+D25 | G25: =G24+E25 | H25: =ROUND(B9+(C9-B9)*5/6,0) | I25: =H25*$B$4 | J25: =H25*$B$5 | K25: =K24+I25 | L25: =L24+J25 | M25: =ROUND(B10+(C10-B10)*5/6,0) | N25: =M25*$B$4 | O25: =M25*$B$5 | P25: =P24+N25 | Q25: =Q24+O25
A26: 12 | B26: 2027-06 | C26: =ROUND(B8+(C8-B8)*6/6,0) | D26: =C26*$B$4 | E26: =C26*$B$5 | F26: =F25+D26 | G26: =G25+E26 | H26: =ROUND(B9+(C9-B9)*6/6,0) | I26: =H26*$B$4 | J26: =H26*$B$5 | K26: =K25+I26 | L26: =L25+J26 | M26: =ROUND(B10+(C10-B10)*6/6,0) | N26: =M26*$B$4 | O26: =M26*$B$5 | P26: =P25+N26 | Q26: =Q25+O26
A27: 13 | B27: 2027-07 | C27: =ROUND(C8+(D8-C8)*1/6,0) | D27: =C27*$B$4 | E27: =C27*$B$5 | F27: =F26+D27 | G27: =G26+E27 | H27: =ROUND(C9+(D9-C9)*1/6,0) | I27: =H27*$B$4 | J27: =H27*$B$5 | K27: =K26+I27 | L27: =L26+J27 | M27: =ROUND(C10+(D10-C10)*1/6,0) | N27: =M27*$B$4 | O27: =M27*$B$5 | P27: =P26+N27 | Q27: =Q26+O27
A28: 14 | B28: 2027-08 | C28: =ROUND(C8+(D8-C8)*2/6,0) | D28: =C28*$B$4 | E28: =C28*$B$5 | F28: =F27+D28 | G28: =G27+E28 | H28: =ROUND(C9+(D9-C9)*2/6,0) | I28: =H28*$B$4 | J28: =H28*$B$5 | K28: =K27+I28 | L28: =L27+J28 | M28: =ROUND(C10+(D10-C10)*2/6,0) | N28: =M28*$B$4 | O28: =M28*$B$5 | P28: =P27+N28 | Q28: =Q27+O28
A29: 15 | B29: 2027-09 | C29: =ROUND(C8+(D8-C8)*3/6,0) | D29: =C29*$B$4 | E29: =C29*$B$5 | F29: =F28+D29 | G29: =G28+E29 | H29: =ROUND(C9+(D9-C9)*3/6,0) | I29: =H29*$B$4 | J29: =H29*$B$5 | K29: =K28+I29 | L29: =L28+J29 | M29: =ROUND(C10+(D10-C10)*3/6,0) | N29: =M29*$B$4 | O29: =M29*$B$5 | P29: =P28+N29 | Q29: =Q28+O29
A30: 16 | B30: 2027-10 | C30: =ROUND(C8+(D8-C8)*4/6,0) | D30: =C30*$B$4 | E30: =C30*$B$5 | F30: =F29+D30 | G30: =G29+E30 | H30: =ROUND(C9+(D9-C9)*4/6,0) | I30: =H30*$B$4 | J30: =H30*$B$5 | K30: =K29+I30 | L30: =L29+J30 | M30: =ROUND(C10+(D10-C10)*4/6,0) | N30: =M30*$B$4 | O30: =M30*$B$5 | P30: =P29+N30 | Q30: =Q29+O30
A31: 17 | B31: 2027-11 | C31: =ROUND(C8+(D8-C8)*5/6,0) | D31: =C31*$B$4 | E31: =C31*$B$5 | F31: =F30+D31 | G31: =G30+E31 | H31: =ROUND(C9+(D9-C9)*5/6,0) | I31: =H31*$B$4 | J31: =H31*$B$5 | K31: =K30+I31 | L31: =L30+J31 | M31: =ROUND(C10+(D10-C10)*5/6,0) | N31: =M31*$B$4 | O31: =M31*$B$5 | P31: =P30+N31 | Q31: =Q30+O31
A32: 18 | B32: 2027-12 | C32: =ROUND(C8+(D8-C8)*6/6,0) | D32: =C32*$B$4 | E32: =C32*$B$5 | F32: =F31+D32 | G32: =G31+E32 | H32: =ROUND(C9+(D9-C9)*6/6,0) | I32: =H32*$B$4 | J32: =H32*$B$5 | K32: =K31+I32 | L32: =L31+J32 | M32: =ROUND(C10+(D10-C10)*6/6,0) | N32: =M32*$B$4 | O32: =M32*$B$5 | P32: =P31+N32 | Q32: =Q31+O32
A33: 19 | B33: 2028-01 | C33: =ROUND(D8+(E8-D8)*1/6,0) | D33: =C33*$B$4 | E33: =C33*$B$5 | F33: =F32+D33 | G33: =G32+E33 | H33: =ROUND(D9+(E9-D9)*1/6,0) | I33: =H33*$B$4 | J33: =H33*$B$5 | K33: =K32+I33 | L33: =L32+J33 | M33: =ROUND(D10+(E10-D10)*1/6,0) | N33: =M33*$B$4 | O33: =M33*$B$5 | P33: =P32+N33 | Q33: =Q32+O33
A34: 20 | B34: 2028-02 | C34: =ROUND(D8+(E8-D8)*2/6,0) | D34: =C34*$B$4 | E34: =C34*$B$5 | F34: =F33+D34 | G34: =G33+E34 | H34: =ROUND(D9+(E9-D9)*2/6,0) | I34: =H34*$B$4 | J34: =H34*$B$5 | K34: =K33+I34 | L34: =L33+J34 | M34: =ROUND(D10+(E10-D10)*2/6,0) | N34: =M34*$B$4 | O34: =M34*$B$5 | P34: =P33+N34 | Q34: =Q33+O34
A35: 21 | B35: 2028-03 | C35: =ROUND(D8+(E8-D8)*3/6,0) | D35: =C35*$B$4 | E35: =C35*$B$5 | F35: =F34+D35 | G35: =G34+E35 | H35: =ROUND(D9+(E9-D9)*3/6,0) | I35: =H35*$B$4 | J35: =H35*$B$5 | K35: =K34+I35 | L35: =L34+J35 | M35: =ROUND(D10+(E10-D10)*3/6,0) | N35: =M35*$B$4 | O35: =M35*$B$5 | P35: =P34+N35 | Q35: =Q34+O35
A36: 22 | B36: 2028-04 | C36: =ROUND(D8+(E8-D8)*4/6,0) | D36: =C36*$B$4 | E36: =C36*$B$5 | F36: =F35+D36 | G36: =G35+E36 | H36: =ROUND(D9+(E9-D9)*4/6,0) | I36: =H36*$B$4 | J36: =H36*$B$5 | K36: =K35+I36 | L36: =L35+J36 | M36: =ROUND(D10+(E10-D10)*4/6,0) | N36: =M36*$B$4 | O36: =M36*$B$5 | P36: =P35+N36 | Q36: =Q35+O36
A37: 23 | B37: 2028-05 | C37: =ROUND(D8+(E8-D8)*5/6,0) | D37: =C37*$B$4 | E37: =C37*$B$5 | F37: =F36+D37 | G37: =G36+E37 | H37: =ROUND(D9+(E9-D9)*5/6,0) | I37: =H37*$B$4 | J37: =H37*$B$5 | K37: =K36+I37 | L37: =L36+J37 | M37: =ROUND(D10+(E10-D10)*5/6,0) | N37: =M37*$B$4 | O37: =M37*$B$5 | P37: =P36+N37 | Q37: =Q36+O37
A38: 24 | B38: 2028-06 | C38: =ROUND(D8+(E8-D8)*6/6,0) | D38: =C38*$B$4 | E38: =C38*$B$5 | F38: =F37+D38 | G38: =G37+E38 | H38: =ROUND(D9+(E9-D9)*6/6,0) | I38: =H38*$B$4 | J38: =H38*$B$5 | K38: =K37+I38 | L38: =L37+J38 | M38: =ROUND(D10+(E10-D10)*6/6,0) | N38: =M38*$B$4 | O38: =M38*$B$5 | P38: =P37+N38 | Q38: =Q37+O38
A39: 25 | B39: 2028-07 | C39: =ROUND(E8+(F8-E8)*1/6,0) | D39: =C39*$B$4 | E39: =C39*$B$5 | F39: =F38+D39 | G39: =G38+E39 | H39: =ROUND(E9+(F9-E9)*1/6,0) | I39: =H39*$B$4 | J39: =H39*$B$5 | K39: =K38+I39 | L39: =L38+J39 | M39: =ROUND(E10+(F10-E10)*1/6,0) | N39: =M39*$B$4 | O39: =M39*$B$5 | P39: =P38+N39 | Q39: =Q38+O39
A40: 26 | B40: 2028-08 | C40: =ROUND(E8+(F8-E8)*2/6,0) | D40: =C40*$B$4 | E40: =C40*$B$5 | F40: =F39+D40 | G40: =G39+E40 | H40: =ROUND(E9+(F9-E9)*2/6,0) | I40: =H40*$B$4 | J40: =H40*$B$5 | K40: =K39+I40 | L40: =L39+J40 | M40: =ROUND(E10+(F10-E10)*2/6,0) | N40: =M40*$B$4 | O40: =M40*$B$5 | P40: =P39+N40 | Q40: =Q39+O40
A41: 27 | B41: 2028-09 | C41: =ROUND(E8+(F8-E8)*3/6,0) | D41: =C41*$B$4 | E41: =C41*$B$5 | F41: =F40+D41 | G41: =G40+E41 | H41: =ROUND(E9+(F9-E9)*3/6,0) | I41: =H41*$B$4 | J41: =H41*$B$5 | K41: =K40+I41 | L41: =L40+J41 | M41: =ROUND(E10+(F10-E10)*3/6,0) | N41: =M41*$B$4 | O41: =M41*$B$5 | P41: =P40+N41 | Q41: =Q40+O41
A42: 28 | B42: 2028-10 | C42: =ROUND(E8+(F8-E8)*4/6,0) | D42: =C42*$B$4 | E42: =C42*$B$5 | F42: =F41+D42 | G42: =G41+E42 | H42: =ROUND(E9+(F9-E9)*4/6,0) | I42: =H42*$B$4 | J42: =H42*$B$5 | K42: =K41+I42 | L42: =L41+J42 | M42: =ROUND(E10+(F10-E10)*4/6,0) | N42: =M42*$B$4 | O42: =M42*$B$5 | P42: =P41+N42 | Q42: =Q41+O42
A43: 29 | B43: 2028-11 | C43: =ROUND(E8+(F8-E8)*5/6,0) | D43: =C43*$B$4 | E43: =C43*$B$5 | F43: =F42+D43 | G43: =G42+E43 | H43: =ROUND(E9+(F9-E9)*5/6,0) | I43: =H43*$B$4 | J43: =H43*$B$5 | K43: =K42+I43 | L43: =L42+J43 | M43: =ROUND(E10+(F10-E10)*5/6,0) | N43: =M43*$B$4 | O43: =M43*$B$5 | P43: =P42+N43 | Q43: =Q42+O43
A44: 30 | B44: 2028-12 | C44: =ROUND(E8+(F8-E8)*6/6,0) | D44: =C44*$B$4 | E44: =C44*$B$5 | F44: =F43+D44 | G44: =G43+E44 | H44: =ROUND(E9+(F9-E9)*6/6,0) | I44: =H44*$B$4 | J44: =H44*$B$5 | K44: =K43+I44 | L44: =L43+J44 | M44: =ROUND(E10+(F10-E10)*6/6,0) | N44: =M44*$B$4 | O44: =M44*$B$5 | P44: =P43+N44 | Q44: =Q43+O44
...

Sheet CAC·채널
A1: CAC 규율 · 채널 · 지원금 배분
A3: 파일럿 CAC 상한(원/명) | B3: 200000 | C3: 상한 초과 채널 사용 금지 · 2주 연속 리드 0이면 채널 교체
A5: 채널 4트랙 (전 채널 1~2개 동 반경 집중)
A6: 트랙 | B6: 대상 | C6: 우선순위/가동 | D6: 핵심 채널 | E6: CAC 가설
A7: T1 학생 | B7: 사용자·가정 내 추천 | C7: 1순위 | D7: 숏폼·AI 무료체험 → 부모님께 보내기 | E7: 콘텐츠 비용
A8: T2 학부모 | B8: 결제자(본진) | C8: 2순위 | D8: 네이버 SA(로컬)·카카오 CRM·당근 비즈프로필 | E8: 결제 CAC 20~50만 원
A9: T3 강사 | B9: 공급(최선행) | C9: 3순위 · 수요보다 2~6주 선행 | D9: 채용 공고 SEO·재직 강사 추천(보너스 10만) | E9: 건당 10만 원
A10: T4 매니저 | B10: 운영 인력 | C10: 4순위 · Gate 2 이후 | D10: 맘카페·당근 구인(지역) | E10: 약 0(겸용)
A12: 시나리오별 CAC
A13: 시나리오 | B13: 초기 CAC(원, 2026 H2) | C13: 안정기 CAC(원, 2028+) | D13: LTV/CAC 목표
A14: 보수 | B14: 300000 | C14: 400000 | D14: 3:1 이상
A15: 기본 | B15: 200000 | C15: 250000 | D15: 5:1 이상
A16: 공격 | B16: 100000 | C16: 150000 | D16: 8:1 이상
A18: LTV(기본 시나리오) 약 130만~200만 원 = 객단가 × 평균 유지 기간 × 마진율. CAC 실측은 GA4·픽셀 도입 이후.
A20: 지원금 1억 원 배분 (예비창업패키지)
A21: 지원금 총액(원) | B21: 100000000
A22: 항목 | B22: 비율 | C22: 금액(원) | D22: 집행 시기 | E22: 세부
A23: 인건비 | B23: 0.3 | C23: =$B$21*B23 | D23: 개시~9개월 | E23: 학습 매니저 1~2인 채용, 대표자는 개발·전략 집중
A24: 사업화(개발) | B24: 0.25 | C24: =$B$21*B24 | D24: 1~9개월 | E24: 모바일 앱 완성·스토어 출시, 빌링키 자동결제, 강사 추천 1차
A25: 마케팅·홍보 | B25: 0.25 | C25: =$B$21*B25 | D25: 전 기간 | E25: 네이버 SA·스마트플레이스·맘카페·카카오 채널, 실촬영·후기 자산
A26: 운영 제반비 | B26: 0.15 | C26: =$B$21*B26 | D26: 초기 집중 | E26: 법인 설립·신고, 법무·세무, 약관·환불정책, 배상책임보험
A27: 예비비 | B27: 0.05 | C27: =$B$21*B27 | D27: 상시 | E27: 환불 대비 준비금·긴급 비용
A28: 합계 | B28: =SUM(B23:B27) | C28: =SUM(C23:C27)
A30: 마케팅 예산 단계: 파일럿 월 30~50만(자력) → 성장기 월 100~300만 → Phase 2 월 200~500만. 지원금 마케팅비 2,500만 원은 전 기간 분할 집행.
